<?xml version="1.0"?>
<robot name="diff_robot">

    <link name="base_link"/>

    <joint name="base_joint" type="fixed">
        <parent link="base_link"/>
        <child link="frame_link"/>
        <origin xyz="-0.1 0.0 0.0" rpy="0.0 0.0 0.0"/>
    </joint>

    <link name="frame_link">
        <visual>
            <geometry>
                <box size="0.4 0.3 0.15"/>
            </geometry>
            <origin xyz="0.2 0.0 0.075" rpy="0.0 0.0 0.0"/>
            <material name="red">
                <color rgba="1.0 0.0 0.0 1.0"/>
            </material>
        </visual>
        <collision>
            <geometry>
                <box size="0.4 0.3 0.15"/>
            </geometry>
            <origin xyz="0.2 0.0 0.075" rpy="0.0 0.0 0.0"/>
        </collision>
        <inertial>
            <mass value="4.0"/>
            <origin xyz="0.2 0.0 0.075"/>
            <inertia ixx="0.1" ixy="0.0" ixz="0.0" iyy="0.1" iyz="0.0" izz="0.1"/>
        </inertial>
    </link>

    <joint name="left_wheel_joint" type="continuous">
        <parent link="base_link"/>
        <child link="left_wheel_link"/>
        <origin xyz="0.0 0.17 0.0" rpy="-1.57 0.0 0.0"/>
        <axis xyz="0.0 0.0 1.0"/>
    </joint>

    <link name="left_wheel_link">
        <visual>
            <geometry>
                <cylinder radius="0.06" length="0.03"/>
            </geometry>
            <origin xyz="0.0 0.0 0.0" rpy="0 0.0 0.0"/>
            <material name="blue">
                <color rgba="0.0 0.0 1.0 1.0"/>
            </material>
        </visual>
        <collision>
            <geometry>
                <cylinder radius="0.06" length="0.03"/>
            </geometry>
            <origin xyz="0.0 0.0 0.0" rpy="0 0.0 0.0"/>
        </collision>
        <inertial>
            <mass value="1.0"/>
            <origin xyz="0.0 0.0 0.0"/>
            <inertia ixx="0.1" ixy="0.0" ixz="0.0" iyy="0.1" iyz="0.0" izz="0.1"/>
        </inertial>
    </link>

    <joint name="right_wheel_joint" type="continuous">
        <parent link="base_link"/>
        <child link="right_wheel_link"/>
        <origin xyz="0.0 -0.17 0.0" rpy="1.57 0.0 0.0"/>
        <axis xyz="0.0 0.0 1.0"/>
    </joint>

    <link name="right_wheel_link">
        <visual>
            <geometry>
                <cylinder radius="0.06" length="0.03"/>
            </geometry>
            <origin xyz="0.0 0.0 0.0" rpy="0 0.0 0.0"/>
            <material name="blue">
                <color rgba="0.0 0.0 1.0 1.0"/>
            </material>
        </visual>
        <collision>
            <geometry>
                <cylinder radius="0.06" length="0.03"/>
            </geometry>
            <origin xyz="0.0 0.0 0.0" rpy="0 0.0 0.0"/>
        </collision>
        <inertial>
            <mass value="1.0"/>
            <origin xyz="0.0 0.0 0.0"/>
            <inertia ixx="0.1" ixy="0.0" ixz="0.0" iyy="0.1" iyz="0.0" izz="0.1"/>
        </inertial>
    </link>

    <joint name="caster_joint" type="fixed">
        <parent link="base_link"/>
        <child link="caster_link"/>
        <origin xyz="0.2 0.0 0.0"/>
    </joint>

    <link name="caster_link">
        <visual>
            <geometry>
                <sphere radius="0.06"/>
            </geometry>
            <material name="yellow">
                <color rgba="1.0 1.0 0.0 1.0"/>
            </material>
        </visual>
        <collision>
            <geometry>
                <sphere radius="0.06"/>
            </geometry>
        </collision>
        <inertial>
            <mass value="1e-5"/>
            <inertia ixx="1e-6" ixy="0" ixz="0" iyy="1e-6" iyz="0" izz="1e-6"/>
        </inertial>
    </link>

    <joint name="camera_joint" type="fixed">
        <parent link="base_link"/>
        <child link="camera_link"/>
        <origin xyz="0.28 0.0 0.19" rpy="0.0 0.26 0.0"/>
    </joint>

    <link name="camera_link">
        <visual>
            <geometry>
                <box size="0.03 0.1 0.06"/>
            </geometry>
            <material name="Purple">
                <color rgba="1.0 0.0 1.0 1.0"/>
            </material>
        </visual>
        <collision>
            <geometry>
                <box size="0.03 0.1 0.06"/>
            </geometry>
        </collision>
        <inertial>
            <mass value="1e-5" />
            <inertia ixx="1e-6" ixy="0" ixz="0" iyy="1e-6" iyz="0" izz="1e-6" />
        </inertial>
    </link>
        <!-- ===================== -->
        <!-- imu_link -->
        <!-- ===================== -->
    <link name="imu_link">
        <inertial>
            <origin xyz="0.1 0 0.15" rpy="0 0 0"/>
            <mass value="0.05"/>
            <inertia ixx="0.00001" ixy="0.0" ixz="0.0"
                     iyy="0.00001" iyz="0.0"
                     izz="0.00001"/>
            </inertial>

        <visual>
            <origin xyz="0.1 0 0.15" rpy="0 0 0"/>
            <geometry>
                <box size="0.03 0.03 0.02"/>
            </geometry>
            <material name="green">
                <color rgba="0.0 1.0 0.0 1.0"/>
            </material>
        </visual>

        <collision>
            <origin xyz="0.1 0 0.15" rpy="0 0 0"/>
        <geometry>
            <box size="0.03 0.03 0.02"/>
        </geometry>
        </collision>
    </link>

    <joint name="imu_joint" type="fixed">
        <origin xyz="0 0 0" rpy="0 0 0"/>
        <parent link="frame_link"/>
        <child link="imu_link"/>
    </joint>


    <gazebo>
        <plugin filename="gz-sim-diff-drive-system" name="gz::sim::systems::DiffDrive">
            <left_joint>left_wheel_joint</left_joint>
            <right_joint>right_wheel_joint</right_joint>
            <wheel_separation>0.34</wheel_separation>
            <wheel_radius>0.06</wheel_radius>
            <topic>/cmd_vel</topic>
        </plugin>

        <plugin filename="gz-sim-joint-state-publisher-system" name="gz::sim::systems::JointStatePublisher"/>
        
        <plugin filename="gz-sim-sensors-system" name="gz::sim::systems::Sensors">
            <render_engine>ogre2</render_engine>
        </plugin>

        <plugin filename="gz-sim-imu-system" name="gz::sim::systems::Imu">
        </plugin>
    </gazebo>

    <gazebo reference="camera_link">
        <sensor type="camera" name="camera1">
            <update_rate>30.0</update_rate>
            <topic>camera/image_raw</topic>
            <gz_frame_id>camera_link</gz_frame_id>
            <camera>
                <horizontal_fov>1.3962634</horizontal_fov>
                <image>
                    <width>800</width>
                    <height>800</height>
                </image>
                <clip>
                    <near>0.02</near>
                    <far>300</far>
                </clip>
            </camera>
        </sensor>
    </gazebo>
    <gazebo reference="imu_link">
		<sensor name="imu_sensor" type="imu">
			<always_on>1</always_on>
			<update_rate>1</update_rate>
			<visualize>true</visualize>
			<topic>imu</topic>

			<imu>
				<angular_velocity>
					<x>
						<noise type="gaussian">
							<mean>0.0</mean>
							<stddev>0.0002</stddev>
						</noise>
					</x>
					<y>
						<noise type="gaussian">
							<mean>0.0</mean>
							<stddev>0.0002</stddev>
						</noise>
					</y>
					<z>
						<noise type="gaussian">
							<mean>0.0</mean>
							<stddev>0.0002</stddev>
						</noise>
					</z>
				</angular_velocity>

				<linear_acceleration>
					<x>
						<noise type="gaussian">
							<mean>0.0</mean>
							<stddev>0.017</stddev>
						</noise>
					</x>
					<y>
						<noise type="gaussian">
							<mean>0.0</mean>
							<stddev>0.017</stddev>
						</noise>
					</y>
					<z>
						<noise type="gaussian">
							<mean>0.0</mean>
							<stddev>0.017</stddev>
						</noise>
					</z>
				</linear_acceleration>
			</imu>

		</sensor>
	</gazebo>

</robot>